<?xml version="1.0" ?>
<!-- =================================================================================== -->
<!-- |    This document was autogenerated by xacro from /home/samee/ros2_ws/src/servo_controller/urdf/fixed_urdf2.urdf | -->
<!-- |    EDITING THIS FILE BY HAND IS NOT RECOMMENDED                                 | -->
<!-- =================================================================================== -->
<robot xmlns:xacro="http://www.ros.org/wiki/xacro"  name="robot">

  <!-- Gazebo plugin for ros2_control -->
  <gazebo>
    <plugin name="gazebo_ros2_control" filename="libgazebo_ros2_control.so">
      <robotNamespace>/</robotNamespace>
    </plugin>
  </gazebo>

  <link name="base_link">
    <visual>
      <geometry>
        <box size="0.254 0.127 0.0635"/>
      </geometry>
    </visual>
    <collision>
      <geometry>
        <box size="0.254 0.127 0.0635"/>
      </geometry>
    </collision>
    <inertial>
      <origin rpy="0.000 0.000 0.000" xyz="0.000 0.000 0.000"/>
      <mass value="2.000"/>
      <inertia ixx="0.03562" ixy="0.00000" ixz="0.00000" iyy="0.04262" iyz="0.00000" izz="0.04508"/>
    </inertial>
  </link>

  <!-- FL -->
  <joint name="hip_fl" type="revolute">
    <limit effort="100" lower="-0.2" upper="0.4" velocity="10"/>
    <origin rpy="0 0 0" xyz="0.0508 0.0508 0"/>
    <parent link="base_link"/>
    <child link="hipbone_fl"/>
    <!-- ros2_control Transmission -->
    <transmission>
      <type>transmission_interface/SimpleTransmission</type>
      <joint name="hip_fl">
        <hardwareInterface>hardware_interface/PositionJointInterface</hardwareInterface>
      </joint>
      <actuator name="hip_fl_motor">
        <hardwareInterface>hardware_interface/PositionJointInterface</hardwareInterface>
        <mechanicalReduction>1</mechanicalReduction>
      </actuator>
    </transmission>
  </joint>

  <link name="hipbone_fl">
    <visual>
      <origin rpy="0 0 0" xyz=" 0.0 0.0 0"/>
      <geometry>
        <box size="0.0635 0.03175 0.0381"/>
      </geometry>
    </visual>
    <collision>
      <origin rpy="0 0 0" xyz=" 0.0 0.0 0"/>
      <geometry>
        <box size="0.0635 0.03175 0.0381"/>
      </geometry>
    </collision>
    <inertial>
      <origin rpy="0.000 0.000 0.000" xyz="0.000 0.000 0.000"/>
      <mass value="0.233"/>
      <inertia ixx="0.00216" ixy="-0.00001" ixz="0.00001" iyy="0.00216" iyz="0.00001" izz="0.00211"/>
    </inertial>
  </link>

  <joint name="shoulder_fl" type="revolute">
    <limit effort="100" lower="-0.1" upper="0.5" velocity="10"/>
    <origin rpy="0 0 0" xyz="0 0 0"/>
    <axis xyz="0 1 0"/>
    <parent link="hipbone_fl"/>
    <child link="femur_fl"/>
    <!-- ros2_control Transmission -->
    <transmission>
      <type>transmission_interface/SimpleTransmission</type>
      <joint name="shoulder_fl">
        <hardwareInterface>hardware_interface/PositionJointInterface</hardwareInterface>
      </joint>
      <actuator name="shoulder_fl_motor">
        <hardwareInterface>hardware_interface/PositionJointInterface</hardwareInterface>
        <mechanicalReduction>1</mechanicalReduction>
      </actuator>
    </transmission>
  </joint>

  <link name="femur_fl">
    <visual>
      <origin rpy="0 0 0" xyz="0.0 0.027 -0.0635"/>
      <geometry>
        <box size="0.0254 0.0254 0.127"/>
      </geometry>
    </visual>
    <collision>
      <origin rpy="0 0 0" xyz="0.0 0.027 -0.0635"/>
      <geometry>
        <box size="0.0254 0.0254 0.127"/>
      </geometry>
    </collision>
    <inertial>
      <origin rpy="0.000 0.000 0.000" xyz="0.000 0.000 0.000"/>
      <mass value="0.084"/>
      <inertia ixx="0.00414" ixy="0.00000" ixz="0.00000" iyy="0.00410" iyz="0.00006" izz="0.00386"/>
    </inertial>
  </link>

  <joint name="knee_fl" type="revolute">
    <limit effort="100" lower="-2" upper="-0.4" velocity="10"/>
    <origin rpy="0 0 1.57" xyz="0 0 -0.127"/>
    <parent link="femur_fl"/>
    <child link="tibia_fl"/>
    <!-- ros2_control Transmission -->
    <transmission>
      <type>transmission_interface/SimpleTransmission</type>
      <joint name="knee_fl">
        <hardwareInterface>hardware_interface/PositionJointInterface</hardwareInterface>
      </joint>
      <actuator name="knee_fl_motor">
        <hardwareInterface>hardware_interface/PositionJointInterface</hardwareInterface>
        <mechanicalReduction>1</mechanicalReduction>
      </actuator>
    </transmission>
  </joint>

  <link name="tibia_fl">
    <visual>
      <origin rpy="0 0 0" xyz="0.0254 0.0 -0.06985"/>
      <geometry>
        <box size="0.00635 0.00635 0.1397"/>
      </geometry>
    </visual>
    <collision>
      <origin rpy="0 0 0" xyz="0.0254 0.0 -0.06985"/>
      <geometry>
        <box size="0.00635 0.00635 0.1397"/>
      </geometry>
    </collision>
    <inertial>
      <origin rpy="0.000 0.000 0.000" xyz="0.000 0.000 0.000"/>
      <mass value="0.034"/>
      <inertia ixx="0.00159" ixy="0.00000" ixz="-0.00001" iyy="0.00159" iyz="0.00000" izz="0.00147"/>
    </inertial>
  </link>

  <!-- FR -->
  <joint name="hip_fr" type="revolute">
    <limit effort="100" lower="-0.2" upper="0.4" velocity="10"/>
    <origin rpy="0 0 3.14" xyz="0.0508 -0.0508 0"/>
    <parent link="base_link"/>
    <child link="hipbone_fr"/>
    <!-- ros2_control Transmission -->
    <transmission>
      <type>transmission_interface/SimpleTransmission</type>
      <joint name="hip_fr">
        <hardwareInterface>hardware_interface/PositionJointInterface</hardwareInterface>
      </joint>
      <actuator name="hip_fr_motor">
        <hardwareInterface>hardware_interface/PositionJointInterface</hardwareInterface>
        <mechanicalReduction>1</mechanicalReduction>
      </actuator>
    </transmission>
  </joint>

  <link name="hipbone_fr">
    <visual>
      <origin rpy="0 0 0" xyz=" 0.0 0.0 0"/>
      <geometry>
        <box size="0.0635 0.03175 0.0381"/>
      </geometry>
    </visual>
    <collision>
      <origin rpy="0 0 0" xyz=" 0.0 0.0 0"/>
      <geometry>
        <box size="0.0635 0.03175 0.0381"/>
      </geometry>
    </collision>
    <inertial>
      <origin rpy="0.000 0.000 0.000" xyz="0.000 0.000 0.000"/>
      <mass value="0.233"/>
      <inertia ixx="0.00216" ixy="0.00001" ixz="0.00001" iyy="0.00216" iyz="-0.00001" izz="0.00211"/>
    </inertial>
  </link>

  <joint name="shoulder_fr" type="revolute">
    <limit effort="100" lower="-0.5" upper="0.1" velocity="10"/>
    <origin rpy="0 0 0" xyz="0 0 0"/>
    <axis xyz="0 1 0"/>
    <parent link="hipbone_fr"/>
    <child link="femur_fr"/>
    <!-- ros2_control Transmission -->
    <transmission>
      <type>transmission_interface/SimpleTransmission</type>
      <joint name="shoulder_fr">
        <hardwareInterface>hardware_interface/PositionJointInterface</hardwareInterface>
      </joint>
      <actuator name="shoulder_fr_motor">
        <hardwareInterface>hardware_interface/PositionJointInterface</hardwareInterface>
        <mechanicalReduction>1</mechanicalReduction>
      </actuator>
    </transmission>
  </joint>

  <link name="femur_fr">
    <visual>
      <origin rpy="0 0 0" xyz="0.0 0.027 -0.0635"/>
      <geometry>
        <box size="0.0254 0.0254 0.127"/>
      </geometry>
    </visual>
    <collision>
      <origin rpy="0 0 0" xyz="0.0 0.027 -0.0635"/>
      <geometry>
        <box size="0.0254 0.0254 0.127"/>
      </geometry>
    </collision>
    <inertial>
      <origin rpy="0.000 0.000 0.000" xyz="0.000 0.000 0.000"/>
      <mass value="0.084"/>
      <inertia ixx="0.00414" ixy="0.00000" ixz="0.00000" iyy="0.00410" iyz="-0.00006" izz="0.00386"/>
    </inertial>
  </link>

  <joint name="knee_fr" type="revolute">
    <limit effort="100" lower="-0.5" upper="2" velocity="10"/>
    <origin rpy="0 0 1.57" xyz="0 0 -0.127"/>
    <parent link="femur_fr"/>
    <child link="tibia_fr"/>
    <!-- ros2_control Transmission -->
    <transmission>
      <type>transmission_interface/SimpleTransmission</type>
      <joint name="knee_fr">
        <hardwareInterface>hardware_interface/PositionJointInterface</hardwareInterface>
      </joint>
      <actuator name="knee_fr_motor">
        <hardwareInterface>hardware_interface/PositionJointInterface</hardwareInterface>
        <mechanicalReduction>1</mechanicalReduction>
      </actuator>
    </transmission>
  </joint>

  <link name="tibia_fr">
    <visual>
      <origin rpy="0 0 0" xyz="0.0254 0.0 -0.06985"/>
      <geometry>
        <box size="0.00635 0.00635 0.1397"/>
      </geometry>
    </visual>
    <collision>
      <origin rpy="0 0 0" xyz="0.0254 0.0 -0.06985"/>
      <geometry>
        <box size="0.00635 0.00635 0.1397"/>
      </geometry>
    </collision>
    <inertial>
      <origin rpy="0.000 0.000 0.000" xyz="0.000 0.000 0.000"/>
      <mass value="0.034"/>
      <inertia ixx="0.00159" ixy="0.00000" ixz="-0.00001" iyy="0.00159" iyz="0.00000" izz="0.00147"/>
    </inertial>
  </link>

  <!-- BR -->
  <joint name="hip_br" type="revolute">
    <limit effort="100" lower="-0.2" upper="0.4" velocity="10"/>
    <origin rpy="0 0 3.14" xyz="-0.0508 -0.0508 0"/>
    <parent link="base_link"/>
    <child link="hipbone_br"/>
    <!-- ros2_control Transmission -->
    <transmission>
      <type>transmission_interface/SimpleTransmission</type>
      <joint name="hip_br">
        <hardwareInterface>hardware_interface/PositionJointInterface</hardwareInterface>
      </joint>
      <actuator name="hip_br_motor">
        <hardwareInterface>hardware_interface/PositionJointInterface</hardwareInterface>
        <mechanicalReduction>1</mechanicalReduction>
      </actuator>
    </transmission>
  </joint>

  <link name="hipbone_br">
    <visual>
      <origin rpy="0 0 0" xyz=" 0.0 0.0 0"/>
      <geometry>
        <box size="0.0635 0.03175 0.0381"/>
      </geometry>
    </visual>
    <collision>
      <origin rpy="0 0 0" xyz=" 0.0 0.0 0"/>
      <geometry>
        <box size="0.0635 0.03175 0.0381"/>
      </geometry>
    </collision>
    <inertial>
      <origin rpy="0.000 0.000 0.000" xyz="0.000 0.000 0.000"/>
      <mass value="0.233"/>
      <inertia ixx="0.00216" ixy="-0.00001" ixz="-0.00001" iyy="0.00216" iyz="-0.00001" izz="0.00211"/>
    </inertial>
  </link>

  <joint name="shoulder_br" type="revolute">
    <limit effort="100" lower="-0.5" upper="0.1" velocity="10"/>
    <origin rpy="0 0 0" xyz="0 0 0"/>
    <axis xyz="0 1 0"/>
    <parent link="hipbone_br"/>
    <child link="femur_br"/>
    <!-- ros2_control Transmission -->
    <transmission>
      <type>transmission_interface/SimpleTransmission</type>
      <joint name="shoulder_br">
        <hardwareInterface>hardware_interface/PositionJointInterface</hardwareInterface>
      </joint>
      <actuator name="shoulder_br_motor">
        <hardwareInterface>hardware_interface/PositionJointInterface</hardwareInterface>
        <mechanicalReduction>1</mechanicalReduction>
      </actuator>
    </transmission>
  </joint>

  <link name="femur_br">
    <visual>
      <origin rpy="0 0 0" xyz="0.0 0.027 -0.0635"/>
      <geometry>
        <box size="0.0254 0.0254 0.127"/>
      </geometry>
    </visual>
    <collision>
      <origin rpy="0 0 0" xyz="0.0 0.027 -0.0635"/>
      <geometry>
        <box size="0.0254 0.0254 0.127"/>
      </geometry>
    </collision>
    <inertial>
      <origin rpy="0.000 0.000 0.000" xyz="0.000 0.000 0.000"/>
      <mass value="0.084"/>
      <inertia ixx="0.00414" ixy="0.00000" ixz="0.00000" iyy="0.00410" iyz="-0.00006" izz="0.00386"/>
    </inertial>
  </link>

  <joint name="knee_br" type="revolute">
    <limit effort="100" lower="-0.5" upper="2" velocity="10"/>
    <origin rpy="0 0 1.57" xyz="0 0 -0.127"/>
    <parent link="femur_br"/>
    <child link="tibia_br"/>
    <!-- ros2_control Transmission -->
    <transmission>
      <type>transmission_interface/SimpleTransmission</type>
      <joint name="knee_br">
        <hardwareInterface>hardware_interface/PositionJointInterface</hardwareInterface>
      </joint>
      <actuator name="knee_br_motor">
        <hardwareInterface>hardware_interface/PositionJointInterface</hardwareInterface>
        <mechanicalReduction>1</mechanicalReduction>
      </actuator>
    </transmission>
  </joint>

  <link name="tibia_br">
    <visual>
      <origin rpy="0 0 0" xyz="0.0254 0.0 -0.06985"/>
      <geometry>
        <box size="0.00635 0.00635 0.1397"/>
      </geometry>
    </visual>
    <collision>
      <origin rpy="0 0 0" xyz="0.0254 0.0 -0.06985"/>
      <geometry>
        <box size="0.00635 0.00635 0.1397"/>
      </geometry>
    </collision>
    <inertial>
      <origin rpy="0.000 0.000 0.000" xyz="0.000 0.000 0.000"/>
      <mass value="0.034"/>
      <inertia ixx="0.00159" ixy="0.00000" ixz="-0.00001" iyy="0.00159" iyz="0.00000" izz="0.00147"/>
    </inertial>
  </link>

  <!-- BL -->
  <joint name="hip_bl" type="revolute">
    <limit effort="100" lower="-0.2" upper="0.4" velocity="10"/>
    <origin rpy="0 0 0" xyz="-0.0508 0.0508 0"/>
    <parent link="base_link"/>
    <child link="hipbone_bl"/>
    <!-- ros2_control Transmission -->
    <transmission>
      <type>transmission_interface/SimpleTransmission</type>
      <joint name="hip_bl">
        <hardwareInterface>hardware_interface/PositionJointInterface</hardwareInterface>
      </joint>
      <actuator name="hip_bl_motor">
        <hardwareInterface>hardware_interface/PositionJointInterface</hardwareInterface>
        <mechanicalReduction>1</mechanicalReduction>
      </actuator>
    </transmission>
  </joint>

  <link name="hipbone_bl">
    <visual>
      <origin rpy="0 0 0" xyz=" 0.0 0.0 0"/>
      <geometry>
        <box size="0.0635 0.03175 0.0381"/>
      </geometry>
    </visual>
    <collision>
      <origin rpy="0 0 0" xyz=" 0.0 0.0 0"/>
      <geometry>
        <box size="0.0635 0.03175 0.0381"/>
      </geometry>
    </collision>
    <inertial>
      <origin rpy="0.000 0.000 0.000" xyz="0.000 0.000 0.000"/>
      <mass value="0.233"/>
      <inertia ixx="0.00216" ixy="0.00001" ixz="-0.00001" iyy="0.00216" iyz="0.00001" izz="0.00211"/>
    </inertial>
  </link>

  <joint name="shoulder_bl" type="revolute">
    <limit effort="100" lower="-0.1" upper="0.5" velocity="10"/>
    <origin rpy="0 0 0" xyz="0 0 0"/>
    <axis xyz="0 1 0"/>
    <parent link="hipbone_bl"/>
    <child link="femur_bl"/>
    <!-- ros2_control Transmission -->
    <transmission>
      <type>transmission_interface/SimpleTransmission</type>
      <joint name="shoulder_bl">
        <hardwareInterface>hardware_interface/PositionJointInterface</hardwareInterface>
      </joint>
      <actuator name="shoulder_bl_motor">
        <hardwareInterface>hardware_interface/PositionJointInterface</hardwareInterface>
        <mechanicalReduction>1</mechanicalReduction>
      </actuator>
    </transmission>
  </joint>

  <link name="femur_bl">
    <visual>
      <origin rpy="0 0 0" xyz="0.0 0.027 -0.0635"/>
      <geometry>
        <box size="0.0254 0.0254 0.127"/>
      </geometry>
    </visual>
    <collision>
      <origin rpy="0 0 0" xyz="0.0 0.027 -0.0635"/>
      <geometry>
        <box size="0.0254 0.0254 0.127"/>
      </geometry>
    </collision>
    <inertial>
      <origin rpy="0.000 0.000 0.000" xyz="0.000 0.000 0.000"/>
      <mass value="0.084"/>
      <inertia ixx="0.00414" ixy="0.00000" ixz="0.00000" iyy="0.00410" iyz="0.00006" izz="0.00386"/>
    </inertial>
  </link>

  <joint name="knee_bl" type="revolute">
    <limit effort="100" lower="-2" upper="-0.4" velocity="10"/>
    <origin rpy="0 0 1.57" xyz="0 0 -0.127"/>
    <parent link="femur_bl"/>
    <child link="tibia_bl"/>
    <!-- ros2_control Transmission -->
    <transmission>
      <type>transmission_interface/SimpleTransmission</type>
      <joint name="knee_bl">
        <hardwareInterface>hardware_interface/PositionJointInterface</hardwareInterface>
      </joint>
      <actuator name="knee_bl_motor">
        <hardwareInterface>hardware_interface/PositionJointInterface</hardwareInterface>
        <mechanicalReduction>1</mechanicalReduction>
      </actuator>
    </transmission>
  </joint>

  <link name="tibia_bl">
    <visual>
      <origin rpy="0 0 0" xyz="0.0254 0.0 -0.06985"/>
      <geometry>
        <box size="0.00635 0.00635 0.1397"/>
      </geometry>
    </visual>
    <collision>
      <origin rpy="0 0 0" xyz="0.0254 0.0 -0.06985"/>
      <geometry>
        <box size="0.00635 0.00635 0.1397"/>
      </geometry>
    </collision>
    <inertial>
      <origin rpy="0.000 0.000 0.000" xyz="0.000 0.000 0.000"/>
      <mass value="0.034"/>
      <inertia ixx="0.00159" ixy="0.00000" ixz="-0.00001" iyy="0.00159" iyz="0.00000" izz="0.00147"/>
    </inertial>
  </link>

  <xacro:include filename="example_gazebo.xacro" />

</robot>
